Workbook

Sheet OJTSummarized
G1: Monitoring and Performance | K1: Monitoring and Observation | O1: Professional Behavior | W1: Professional Relations | AB1: Professional Performance | AK1: Professional Knowledege | AN1: Attitude | AQ1: Monitoring and Observation | AT1: Knowledge and Skills
A2: Group Incharge | B2: Host Training Establishment | C2: Mode of Delivery | D2: Section | E2: Name of Student Intern | F2: Attendance | G2: A.Quality of Work | H2: B. Punctuality & Time Management | I2: C. Team Collaboration & Communication | J2: MP Sum | K2: A. Adaptability and Learning | L2: B. Professionalism & Attitude | M2: MO SUm | N2: IMEF Sum | O2: A. professional appearance | P2: B. Seeks responsibility | Q2: C. Demonstrates initiative | R2: D. Dependently | S2: E. Accepts direction and constructive criticism | T2: F. Ability to work independently | U2: G. Motivation | V2: H. Resourcefulness | W2: A. Rapport with staff | X2: B. Interaction with the public | Y2: C. Understands the need of clients | Z2: D. Ability to plan for clients needs | AA2: E. Adaptability | AB2: A. Planning and organizing work schedule | AC2: B. Judgement | AD2: C. Task accomplishment | AE2: D. Oral communication | AF2: E. Written communication | AG2: F. Evaltuation, self-improvement | AH2: G. Leadershiip ability | AI2: H. Quantity of work | AJ2: I. Quality of work | AK2: A. Understanding of agency's goals and operations | AL2: B. Knowledge of field or industry | AM2: Over all rating of intern/student trainee's performance | AN2: A. Regularity in attendance/reporting | AO2: B. Timeliness in the submission of reports | AP2: C. Social relation with practicum | AQ2: A. Sense of responsibility | AR2: B. Level of interest | AS2: C. Level of cooperation | AT2: A. Mastery of the nature work | AU2: B. Quality of work/report | AV2: C. Physical and mental alertness | AW2: Total
A3: Group 1 | B3: University of Kratie | C3: Online | D3: BSIT 4A | E3: Arenas, Christian S. | F3: 4 | G3: 3 | H3: 2 | I3: 1 | J3: =SUM(G3:I3) -> 6 | K3: 1 | L3: 2 | M3: =SUM(K3:L3) -> 3 | N3: =F3+J3+M3 -> 13 | O3: 2 | P3: 2 | Q3: 2 | R3: 2 | S3: 2 | T3: 2 | U3: 2 | V3: 2 | W3: 2 | X3: 2 | Y3: 2 | Z3: 2 | AA3: 2 | AB3: 2 | AC3: 2 | AE3: 2 | AF3: 2 | AG3: 2 | AH3: 2 | AK3: 2 | AL3: 2 | AN3: 4 | AO3: 4 | AP3: 4 | AQ3: 4 | AR3: 4 | AS3: 4 | AT3: 4 | AU3: 4 | AV3: 4 | AW3: =SUM(AN3:AV3) -> 36
A4: Group 1 | B4: Management Information System | C4: Onsite | D4: BSIT 4A | E4: Blas, Ivan Justine L. | F4: 5 | G4: 4 | H4: 3 | I4: 2 | J4: =SUM(G4:I4) -> 9 | K4: 2 | L4: 3 | M4: =SUM(K4:L4) -> 5 | N4: =F4+J4+M4 -> 19 | O4: 96 | P4: 96 | Q4: 96 | R4: 70 | S4: 95 | T4: 95 | U4: 96 | V4: 95 | W4: 95 | X4: 95 | Y4: 95 | Z4: 94 | AA4: 94 | AB4: 95 | AC4: 95 | AD4: 90 | AE4: 90 | AF4: 95 | AG4: 93 | AH4: 95 | AI4: 95 | AJ4: 96 | AK4: 96 | AL4: 96 | AM4: =ROUND(AVERAGE(O4:AL4), 2) -> 93.67 | AN4: 4 | AO4: 4 | AP4: 4 | AQ4: 4 | AR4: 4 | AS4: 4 | AT4: 3 | AU4: 4 | AV4: 3 | AW4: =SUM(AN4:AV4) -> 34
A5: Group 1 | B5: Schools Division Office of City of Baliwag | C5: Onsite | D5: BSIT 4A | E5: Garlan, John Patrick Dr. | F5: 4 | G5: 3 | H5: 2 | I5: 1 | J5: =SUM(G5:I5) -> 6 | K5: 1 | L5: 2 | M5: =SUM(K5:L5) -> 3 | N5: =F5+J5+M5 -> 13 | O5: 100 | P5: 100 | Q5: 100 | R5: 100 | S5: 100 | T5: 100 | U5: 100 | V5: 100 | W5: 100 | X5: 100 | Y5: 100 | Z5: 100 | AA5: 100 | AB5: 100 | AC5: 100 | AD5: 100 | AE5: 100 | AF5: 100 | AG5: 100 | AH5: 100 | AI5: 100 | AJ5: 100 | AK5: 100 | AL5: 100 | AM5: =ROUND(AVERAGE(O5:AL5), 2) -> 100 | AN5: 4 | AO5: 4 | AP5: 4 | AQ5: 4 | AR5: 4 | AS5: 4 | AT5: 4 | AU5: 4 | AV5: 4 | AW5: =SUM(AN5:AV5) -> 36
A6: Group 1 | B6: University of Kratie | C6: Online | D6: BSIT 4A | E6: Payawal, Ronaldo F. | F6: 4 | G6: 4 | H6: 2 | I6: 2 | J6: =SUM(G6:I6) -> 8 | K6: 2 | L6: 2 | M6: =SUM(K6:L6) -> 4 | N6: =F6+J6+M6 -> 16 | O6: 2 | P6: 2 | R6: 3 | S6: 3 | T6: 3 | U6: 3 | V6: 3 | W6: 2 | X6: 2 | Y6: 3 | Z6: 3 | AA6: 3 | AB6: 3 | AC6: 3 | AD6: 2 | AE6: 3 | AF6: 3 | AG6: 2 | AH6: 2 | AK6: 3 | AL6: 3 | AM6: =ROUND(AVERAGE(O6:AL6),0) -> 3 | AN6: 4 | AO6: 3 | AP6: 3 | AQ6: 4 | AR6: 4 | AS6: 4 | AT6: 3 | AU6: 3 | AV6: 3 | AW6: =SUM(AN6:AV6) -> 31
A7: Group 1 | B7: University of Kratie | C7: Online | D7: BSIT 4A | E7: Aquino, Carl Angelo L. | F7: 4 | G7: 4 | H7: 2 | I7: 1 | J7: =SUM(G7:I7) -> 7 | K7: 1 | L7: 2 | M7: =SUM(K7:L7) -> 3 | N7: =F7+J7+M7 -> 14 | O7: 3 | P7: 3 | Q7: 3 | R7: 3 | S7: 3 | T7: 3 | U7: 3 | V7: 2 | W7: 2 | X7: 2 | Y7: 2 | Z7: 3 | AA7: 3 | AB7: 2 | AC7: 2 | AD7: 2 | AE7: 2 | AF7: 2 | AG7: 2 | AH7: 2 | AK7: 3 | AL7: 2 | AM7: =ROUND(AVERAGE(O7:AL7),0) -> 2 | AN7: 4 | AO7: 3 | AP7: 4 | AQ7: 4 | AR7: 4 | AS7: 4 | AT7: 3 | AU7: 4 | AV7: 4 | AW7: =SUM(AN7:AV7) -> 34
A8: Group 1 | B8: Schools Division Office of City of Baliwag | C8: Online | D8: BSIT 4A | E8: Arunas, Joseph Dominic B. | F8: 8 | G8: 3 | H8: 2 | I8: 1 | J8: =SUM(G8:I8) -> 6 | K8: 1 | L8: 2 | M8: =SUM(K8:L8) -> 3 | N8: =F8+J8+M8 -> 17 | O8: 100 | P8: 100 | Q8: 100 | R8: 100 | S8: 100 | T8: 100 | U8: 100 | V8: 100 | W8: 100 | X8: 100 | Y8: 100 | Z8: 100 | AA8: 100 | AB8: 100 | AC8: 100 | AD8: 100 | AE8: 100 | AF8: 100 | AG8: 100 | AH8: 100 | AI8: 100 | AJ8: 100 | AK8: 100 | AL8: 100 | AM8: =ROUND(AVERAGE(O8:AL8), 2) -> 100 | AN8: 4 | AO8: 4 | AP8: 4 | AQ8: 4 | AR8: 4 | AS8: 4 | AT8: 4 | AU8: 4 | AV8: 4 | AW8: =SUM(AN8:AV8) -> 36
A9: Group 1 | B9: Schools Division Office of City of Baliwag | C9: Onsite | D9: BSIT 4A | E9: Baro, Marlon M. | F9: 5 | G9: 3 | H9: 2 | I9: 1 | J9: =SUM(G9:I9) -> 6 | K9: 1 | L9: 2 | M9: =SUM(K9:L9) -> 3 | N9: =F9+J9+M9 -> 14 | O9: 100 | P9: 100 | Q9: 100 | R9: 100 | S9: 100 | T9: 100 | U9: 100 | V9: 100 | W9: 100 | X9: 100 | Y9: 100 | Z9: 100 | AA9: 100 | AB9: 100 | AC9: 100 | AD9: 100 | AE9: 100 | AF9: 100 | AG9: 100 | AH9: 100 | AI9: 100 | AJ9: 100 | AK9: 100 | AL9: 100 | AM9: =ROUND(AVERAGE(O9:AL9), 2) -> 100 | AN9: 4 | AO9: 4 | AP9: 4 | AQ9: 4 | AR9: 4 | AS9: 4 | AT9: 4 | AU9: 4 | AV9: 4 | AW9: =SUM(AN9:AV9) -> 36
A10: Group 1 | B10: YML group Outsource Manila Inc | C10: Onsite | D10: BSIT 4A | E10: Bernardo, Jayvee L. | F10: 3 | G10: 3 | H10: 2 | I10: 1 | J10: =SUM(G10:I10) -> 6 | K10: 1 | L10: 2 | M10: =SUM(K10:L10) -> 3 | N10: =F10+J10+M10 -> 12 | O10: 91 | P10: 91 | Q10: 91 | R10: 91 | S10: 91 | T10: 90 | U10: 90 | V10: 91 | W10: 90 | X10: 90 | Y10: 90 | Z10: 90 | AA10: 90 | AB10: 90 | AC10: 90 | AD10: 91 | AE10: 90 | AF10: 91 | AG10: 91 | AH10: 85 | AI10: 85 | AJ10: 85 | AK10: 91 | AL10: 90 | AM10: =ROUND(AVERAGE(O10:AL10), 2) -> 89.79 | AN10: 2 | AO10: 2 | AP10: 3 | AQ10: 3 | AR10: 3 | AS10: 3 | AT10: 3 | AU10: 3 | AV10: 3 | AW10: =SUM(AN10:AV10) -> 25
A11: Group 1 | B11: Management Information System | C11: Onsite | D11: BSIT 4A | E11: Buco, Christian Dave O. | F11: 4 | G11: 3 | H11: 1 | I11: 1 | J11: =SUM(G11:I11) -> 5 | K11: 2 | L11: 2 | M11: =SUM(K11:L11) -> 4 | N11: =F11+J11+M11 -> 13 | O11: 96 | P11: 92 | Q11: 92 | R11: 91 | S11: 94 | T11: 93 | U11: 97 | V11: 93 | W11: 95 | X11: 97 | Y11: 94 | Z11: 94 | AA11: 95 | AB11: 95 | AC11: 93 | AD11: 96 | AE11: 97 | AF11: 94 | AG11: 92 | AH11: 94 | AI11: 92 | AJ11: 97 | AK11: 93 | AL11: 97 | AM11: =ROUND(AVERAGE(O11:AL11), 2) -> 94.29 | AN11: 2 | AO11: 4 | AP11: 4 | AQ11: 3 | AR11: 4 | AS11: 4 | AT11: 3 | AU11: 4 | AV11: 4 | AW11: =SUM(AN11:AV11) -> 32
A12: Group 1 | B12: WT Mirgmo Systems Inc. | C12: Online | D12: BSIT 4A | E12: Dumlao, Aljohn P. | F12: 4 | G12: 3 | H12: 2 | I12: 1 | J12: =SUM(G12:I12) -> 6 | K12: 1 | L12: 2 | M12: =SUM(K12:L12) -> 3 | N12: =F12+J12+M12 -> 13 | O12: N/A | P12: 100 | Q12: 96 | R12: 95 | S12: 100 | T12: 100 | U12: 100 | V12: 95 | W12: 95 | X12: 100 | Y12: 95 | Z12: 90 | AA12: 95 | AB12: 100 | AC12: 96 | AD12: 96 | AE12: 97 | AF12: 100 | AG12: 100 | AH12: N/A | AI12: 100 | AJ12: 100 | AK12: 100 | AL12: 100 | AM12: =ROUND(AVERAGE(O12:AL12), 2) -> 97.73 | AN12: 4 | AO12: 3 | AP12: 4 | AQ12: 4 | AR12: 4 | AS12: 4 | AT12: 4 | AU12: 3 | AV12: 4 | AW12: =SUM(AN12:AV12) -> 34
A13: Group 1 | B13: Schools Division Office of City of Baliwag | C13: Onsite | D13: BSIT 4A | E13: Flores, John Patrick D. | F13: 5 | G13: 3 | H13: 2 | I13: 1 | J13: =SUM(G13:I13) -> 6 | K13: 1 | L13: 2 | M13: =SUM(K13:L13) -> 3 | N13: =F13+J13+M13 -> 14 | O13: 100 | P13: 100 | Q13: 100 | R13: 100 | S13: 100 | T13: 100 | U13: 100 | V13: 100 | W13: 100 | X13: 100 | Y13: 100 | Z13: 100 | AA13: 100 | AB13: 100 | AC13: 100 | AD13: 100 | AE13: 100 | AF13: 100 | AG13: 100 | AH13: 100 | AI13: 100 | AJ13: 100 | AK13: 100 | AL13: 100 | AM13: =ROUND(AVERAGE(O13:AL13), 2) -> 100 | AN13: 4 | AO13: 4 | AP13: 4 | AQ13: 4 | AR13: 4 | AS13: 4 | AT13: 4 | AU13: 4 | AV13: 4 | AW13: =SUM(AN13:AV13) -> 36
A14: Group 1 | B14: Intellectual Property and Technology Business Management Office | C14: Onsite | D14: BSIT 4A | E14: Francisco, Alvin P. | F14: 3 | G14: 3 | H14: 2 | I14: 1 | J14: =SUM(G14:I14) -> 6 | K14: 1 | L14: 2 | M14: =SUM(K14:L14) -> 3 | N14: =F14+J14+M14 -> 12 | O14: 91 | P14: 92 | Q14: 92 | R14: 88 | S14: 94 | T14: 94 | U14: 98 | V14: 88 | W14: 98 | X14: 91 | Y14: 91 | Z14: 92 | AA14: 94 | AB14: 93 | AC14: 91 | AD14: 98 | AE14: 91 | AF14: 88 | AG14: 92 | AH14: 92 | AI14: 96 | AJ14: 96 | AK14: 91 | AL14: 98 | AM14: =ROUND(AVERAGE(O14:AL14), 2) -> 92.88 | AN14: 4 | AO14: 4 | AP14: 4 | AQ14: 4 | AR14: 3 | AS14: 4 | AT14: 4 | AU14: 4 | AV14: 3 | AW14: =SUM(AN14:AV14) -> 34
A15: Group 1 | B15: Ameticia Digital Marketing | C15: Hybrid | D15: BSIT 4A | E15: Garcia, Nicole C. | F15: 3 | G15: 4 | H15: 2 | I15: 2 | J15: =SUM(G15:I15) -> 8 | K15: 2 | L15: 3 | M15: =SUM(K15:L15) -> 5 | N15: =F15+J15+M15 -> 16 | O15: 98 | P15: 98 | Q15: 97 | R15: 99 | S15: 100 | T15: 98 | U15: 97 | V15: 95 | W15: 98 | X15: 97 | Y15: 95 | Z15: 95 | AA15: 93 | AB15: 98 | AC15: 97 | AD15: 98 | AE15: 97 | AF15: 92 | AG15: 99 | AH15: 93 | AI15: 98 | AJ15: 98 | AK15: 97 | AL15: 95 | AM15: =ROUND(AVERAGE(O15:AL15), 2) -> 96.75 | AN15: 4 | AO15: 3 | AP15: 4 | AQ15: 3 | AR15: 4 | AS15: 4 | AT15: 3 | AU15: 3 | AV15: 3 | AW15: =SUM(AN15:AV15) -> 31
A16: Group 1 | B16: Schools Division Office of City of Baliwag | C16: Onsite | D16: BSIT 4A | E16: Mempin, Jerome C. | F16: 5 | G16: 3 | H16: 2 | I16: 1 | J16: =SUM(G16:I16) -> 6 | K16: 1 | L16: 2 | M16: =SUM(K16:L16) -> 3 | N16: =F16+J16+M16 -> 14 | O16: 100 | P16: 100 | Q16: 100 | R16: 100 | S16: 100 | T16: 100 | U16: 100 | V16: 100 | W16: 100 | X16: 100 | Y16: 100 | Z16: 100 | AA16: 100 | AB16: 100 | AC16: 100 | AD16: 100 | AE16: 100 | AF16: 100 | AG16: 100 | AH16: 100 | AI16: 100 | AJ16: 100 | AK16: 100 | AL16: 100 | AM16: =ROUND(AVERAGE(O16:AL16), 2) -> 100 | AN16: 4 | AO16: 4 | AP16: 4 | AQ16: 4 | AR16: 4 | AS16: 4 | AT16: 4 | AU16: 4 | AV16: 4 | AW16: =SUM(AN16:AV16) -> 36
A17: Group 1 | B17: WT Mirgmo Systems Inc. | C17: Online | D17: BSIT 4A | E17: Milosantos, Raiza B. | F17: 4 | G17: 3 | H17: 2 | I17: 1 | J17: =SUM(G17:I17) -> 6 | K17: 1 | L17: 2 | M17: =SUM(K17:L17) -> 3 | N17: =F17+J17+M17 -> 13 | O17: 90 | P17: 92 | Q17: 91 | R17: 90 | S17: 93 | T17: 95 | U17: 95 | V17: 95 | W17: 95 | X17: 93 | Y17: 93 | Z17: 92 | AA17: 93 | AB17: 92 | AC17: 95 | AD17: 90 | AE17: 95 | AF17: 93 | AG17: 92 | AH17: 93 | AI17: 90 | AJ17: 90 | AK17: 95 | AL17: 95 | AM17: 93.26 | AN17: 3 | AO17: 3 | AP17: 4 | AQ17: 4 | AR17: 4 | AS17: 4 | AT17: 4 | AU17: 4 | AV17: 4 | AW17: =SUM(AN17:AV17) -> 34
A18: Group 1 | B18: BASC - IPTBMO | C18: Onsite | D18: BSIT 4A | E18: Mulato, Cooline T. | F18: 4 | G18: 4 | H18: 3 | I18: 1 | J18: =SUM(G18:I18) -> 8 | K18: 1 | L18: 3 | M18: =SUM(K18:L18) -> 4 | N18: =F18+J18+M18 -> 16 | O18: 94 | P18: 92 | Q18: 98 | R18: 92 | S18: 98 | T18: 88 | U18: 97 | V18: 89 | W18: 93 | X18: 90 | Y18: 90 | Z18: 91 | AA18: 97 | AB18: 94 | AC18: 91 | AD18: 91 | AE18: 91 | AF18: 91 | AG18: 91 | AH18: 88 | AI18: 92 | AJ18: 92 | AK18: 87 | AL18: 93 | AM18: =ROUND(AVERAGE(O18:AL18), 2) -> 92.08 | AN18: 4 | AO18: 4 | AP18: 4 | AQ18: 4 | AR18: 4 | AS18: 4 | AT18: 3 | AU18: 4 | AV18: 4 | AW18: =SUM(AN18:AV18) -> 35
A19: Group 1 | B19: Grass Residences Condominium Corporation | C19: Onsite | D19: BSIT 4A | E19: Orbigoso, Angelito | F19: 4 | G19: 4 | H19: 2 | I19: 2 | J19: =SUM(G19:I19) -> 8 | K19: 2 | L19: 2 | M19: =SUM(K19:L19) -> 4 | N19: =F19+J19+M19 -> 16 | O19: 98 | P19: 98 | Q19: 100 | R19: 98 | S19: 100 | T19: 100 | U19: 98 | V19: 100 | W19: 100 | X19: 98 | Y19: 98 | Z19: 100 | AA19: 99 | AB19: 98 | AC19: 98 | AD19: 100 | AE19: 99 | AF19: 98 | AG19: 100 | AH19: 98 | AI19: 100 | AJ19: 100 | AK19: 98 | AL19: 98 | AM19: =ROUND(AVERAGE(O19:AL19), 2) -> 98.92 | AN19: 4 | AO19: 4 | AP19: 4 | AQ19: 4 | AR19: 4 | AS19: 4 | AT19: 4 | AU19: 4 | AV19: 4 | AW19: =SUM(AN19:AV19) -> 36
A20: Group 1 | B20: Inspiro Relia Inc. | C20: Online | D20: BSIT 4A | E20: Osmillo, Tiffany Jane S.M. | F20: 4 | G20: 4 | H20: 3 | I20: 2 | J20: =SUM(G20:I20) -> 9 | K20: 2 | L20: 2 | M20: =SUM(K20:L20) -> 4 | N20: =F20+J20+M20 -> 17 | O20: 100 | P20: 100 | Q20: 95 | R20: 95 | S20: 100 | T20: 100 | U20: 95 | V20: 95 | W20: 95 | X20: 100 | Y20: 100 | Z20: 100 | AA20: 95 | AB20: 100 | AC20: 100 | AD20: 100 | AE20: 95 | AF20: 100 | AG20: 100 | AH20: 100 | AI20: 95 | AJ20: 100 | AK20: 100 | AL20: 100 | AM20: =ROUND(AVERAGE(O20:AL20), 2) -> 98.33 | AN20: 4 | AO20: 4 | AP20: 4 | AQ20: 4 | AR20: 4 | AS20: 4 | AT20: 4 | AU20: 4 | AV20: 4 | AW20: =SUM(AN20:AV20) -> 36
A21: Group 1 | B21: Management Information System | C21: Onsite | D21: BSIT 4A | E21: Palma, Kyle Marc C. | F21: 5 | G21: 5 | H21: 2 | I21: 2 | J21: =SUM(G21:I21) -> 9 | K21: 2 | L21: 3 | M21: =SUM(K21:L21) -> 5 | N21: =F21+J21+M21 -> 19 | O21: 98 | P21: 95 | Q21: 93 | R21: 95 | S21: 95 | T21: 98 | U21: 99 | V21: 95 | W21: 95 | X21: 97 | Y21: 98 | Z21: 95 | AA21: 95 | AB21: 96 | AC21: 95 | AD21: 98 | AE21: 95 | AF21: 95 | AG21: 96 | AH21: 96 | AI21: 98 | AJ21: 96 | AK21: 95 | AL21: 97 | AM21: =ROUND(AVERAGE(O21:AL21), 2) -> 96.04 | AN21: 4 | AO21: 4 | AP21: 4 | AQ21: 3 | AR21: 4 | AS21: 4 | AT21: 4 | AU21: 4 | AV21: 4 | AW21: =SUM(AN21:AV21) -> 35
A22: Group 1 | B22: University of Kratie | C22: Online | D22: BSIT 4A | E22: Piczon, Francesca V. | F22: 3 | G22: 3 | H22: 2 | I22: 1 | J22: =SUM(G22:I22) -> 6 | K22: 1 | L22: 2 | M22: =SUM(K22:L22) -> 3 | N22: =F22+J22+M22 -> 12 | O22: 2 | P22: 3 | Q22: 2 | R22: 2 | S22: 2 | T22: 2 | U22: 2 | V22: 2 | W22: 2 | X22: 2 | Y22: 2 | Z22: 2 | AA22: 2 | AB22: 2 | AC22: 2 | AD22: 2 | AE22: 2 | AF22: 2 | AG22: 2 | AH22: 2 | AK22: 2 | AL22: 2 | AM22: =ROUND(AVERAGE(O22:AL22),0) -> 2 | AN22: 3 | AO22: 3 | AP22: 3 | AQ22: 3 | AR22: 3 | AS22: 3 | AT22: 3 | AU22: 3 | AV22: 3 | AW22: =SUM(AN22:AV22) -> 27
A23: Group 1 | B23: Panrama Technologies Enterprises | C23: Onsite | D23: BSIT 4A | E23: Purificacion, John Kenrick N. | F23: 2 | G23: 3 | H23: 2 | I23: 1 | J23: =SUM(G23:I23) -> 6 | K23: 1 | L23: 2 | M23: =SUM(K23:L23) -> 3 | N23: =F23+J23+M23 -> 11 | O23: 3 | P23: 3 | Q23: 3 | R23: 3 | S23: 3 | T23: 2 | U23: 3 | V23: 3 | W23: 3 | X23: 2 | Y23: 2 | Z23: 2 | AA23: 3 | AB23: 2 | AC23: 2 | AD23: 2 | AE23: 3 | AF23: 3 | AG23: 3 | AH23: 3 | AK23: 3 | AL23: 3 | AM23: =ROUND(AVERAGE(O23:AL23),0) -> 3 | AN23: 4 | AO23: 4 | AP23: 4 | AQ23: 4 | AR23: 3 | AS23: 3 | AT23: 3 | AU23: 4 | AV23: 4 | AW23: =SUM(AN23:AV23) -> 33
A24: Group 1 | B24: YML group Outsource Manila Inc | C24: Onsite | D24: BSIT 4A | E24: Tianes, Ivy May D. | F24: 3 | G24: 3 | H24: 2 | I24: 1 | J24: =SUM(G24:I24) -> 6 | K24: 1 | L24: 2 | M24: =SUM(K24:L24) -> 3 | N24: =F24+J24+M24 -> 12 | O24: 91 | P24: 91 | Q24: 91 | R24: 91 | S24: 91 | T24: 90 | U24: 90 | V24: 91 | W24: 90 | X24: 90 | Y24: 90 | Z24: 90 | AA24: 90 | AB24: 90 | AC24: 90 | AD24: 91 | AE24: 90 | AF24: 91 | AG24: 90 | AH24: 85 | AI24: 90 | AJ24: 90 | AK24: 91 | AL24: 90 | AM24: =ROUND(AVERAGE(O24:AL24), 2) -> 90.17 | AN24: 2 | AO24: 3 | AP24: 3 | AQ24: 2 | AR24: 3 | AS24: 3 | AT24: 3 | AU24: 3 | AV24: 3 | AW24: =SUM(AN24:AV24) -> 25
A25: Group 1 | B25: APCargo Logistic Network Corporation | C25: Onsite | D25: BSIT 4A | E25: Tiglao, John Mark S, | F25: 5 | G25: 5 | H25: 3 | I25: 2 | J25: =SUM(G25:I25) -> 10 | K25: 2 | L25: 2 | M25: =SUM(K25:L25) -> 4 | N25: =F25+J25+M25 -> 19 | O25: 98 | P25: 97 | Q25: 98 | R25: 97 | S25: 98 | T25: 99 | U25: 98 | V25: 97 | W25: 99 | X25: 100 | Y25: 98 | Z25: 98 | AA25: 98 | AB25: 97 | AC25: 98 | AD25: 99 | AE25: 100 | AF25: 97 | AG25: 98 | AH25: 97 | AI25: 98 | AJ25: 98 | AK25: 99 | AL25: 99 | AM25: =ROUND(AVERAGE(O25:AL25), 2) -> 98.13 | AN25: 4 | AO25: 4 | AP25: 4 | AQ25: 4 | AR25: 4 | AS25: 4 | AT25: 4 | AU25: 4 | AV25: 4 | AW25: =SUM(AN25:AV25) -> 36
A26: Group 1 | B26: BASC - Public Affairs and Information Office | C26: Onsite | D26: BSIT 4A | E26: Vergara, Kristel Kate B. | F26: 3 | G26: 3 | H26: 2 | I26: 1 | J26: =SUM(G26:I26) -> 6 | K26: 1 | L26: 2 | M26: =SUM(K26:L26) -> 3 | N26: =F26+J26+M26 -> 12 | O26: 90 | P26: 92 | Q26: 90 | R26: 90 | S26: 92 | T26: 86 | U26: 90 | V26: 88 | W26: 95 | X26: 89 | Y26: 90 | Z26: 90 | AA26: 92 | AB26: 90 | AC26: 88 | AD26: 92 | AE26: 86 | AF26: 88 | AG26: 90 | AH26: 86 | AI26: 92 | AJ26: 90 | AK26: 90 | AL26: 86 | AM26: =ROUND(AVERAGE(O26:AL26), 2) -> 89.67 | AN26: 3 | AO26: 3 | AP26: 3 | AQ26: 4 | AR26: 3 | AS26: 4 | AT26: 3 | AU26: 3 | AV26: 3 | AW26: =SUM(AN26:AV26) -> 29
A27: Group 1 | B27: Moriroku Philippines Inc | C27: Online | D27: BSIT 4A | E27: Laurente, Ivan F. | F27: 4 | G27: 4 | H27: 2 | I27: 2 | J27: =SUM(G27:I27) -> 8 | K27: 1 | L27: 2 | M27: =SUM(K27:L27) -> 3 | N27: =F27+J27+M27 -> 15 | O27: 91 | P27: 95 | Q27: 95 | R27: 91 | S27: 96 | T27: 91 | U27: 96 | V27: 96 | W27: 96 | X27: 96 | Y27: 96 | Z27: 91 | AA27: 91 | AB27: 95 | AC27: 90 | AD27: 96 | AE27: 91 | AF27: 91 | AG27: 96 | AH27: 91 | AI27: 96 | AJ27: 100 | AK27: 100 | AL27: 100 | AM27: =ROUND(AVERAGE(O27:AL27),0) -> 94 | AN27: 4 | AO27: 4 | AP27: 4 | AQ27: 4 | AR27: 4 | AS27: 4 | AT27: 4 | AU27: 4 | AV27: 3 | AW27: =SUM(AN27:AV27) -> 35
A28: Group 1 | B28: I-Ride Mototranspo Urban or Passenger Land Transportation | C28: Hybrid | D28: BSIT 4B | E28: Serrano, Giff D. | F28: 5 | G28: 5 | H28: 3 | I28: 2 | J28: =SUM(G28:I28) -> 10 | K28: 2 | L28: 2 | M28: =SUM(K28:L28) -> 4 | N28: =F28+J28+M28 -> 19 | O28: 3 | P28: 3 | Q28: 3 | R28: 3 | S28: 2 | T28: 2 | U28: 2 | V28: 2 | W28: 2 | X28: 3 | Y28: 2 | Z28: 3 | AA28: 3 | AB28: 3 | AC28: 3 | AD28: 2 | AE28: 1 | AF28: 1 | AG28: 2 | AH28: 2 | AK28: 1.75 | AL28: 1.75 | AM28: =ROUND(AVERAGE(O28:AL28),0) -> 2 | AN28: 3 | AO28: 3 | AP28: 3 | AQ28: 4 | AR28: 4 | AS28: 4 | AT28: 4 | AU28: 3 | AV28: 3 | AW28: =SUM(AN28,AO28,AP28,AQ28,AR28,AS28,AT28,AU28,AV28) -> 31
A29: Group 1 | B29: I-Ride Mototranspo Urban or Passenger Land Transportation | C29: Hybrid | D29: BSIT 4B | E29: Domingo, Earl Gerald D. | F29: 2 | G29: 3 | H29: 2 | I29: 2 | J29: =SUM(G29:I29) -> 7 | K29: 2 | L29: 2 | M29: =SUM(K29:L29) -> 4 | N29: =F29+J29+M29 -> 13 | O29: 3 | P29: 3 | Q29: 3 | R29: 3 | S29: 3 | T29: 3 | U29: 3 | V29: 3 | W29: 3 | X29: 3 | Y29: 3 | Z29: 3 | AA29: 3 | AB29: 3 | AC29: 3 | AD29: 3 | AE29: 3 | AF29: 3 | AG29: 3 | AH29: 3 | AK29: 2.5 | AL29: 2.5 | AM29: =ROUND(AVERAGE(O29:AL29),0) -> 3 | AN29: 4 | AO29: 4 | AP29: 4 | AQ29: 4 | AR29: 4 | AS29: 4 | AT29: 4 | AW29: =SUM(AN29,AO29,AP29,AQ29,AR29,AS29,AT29,AU29,AV29) -> 28
A30: Group 1 | B30: Management Information System | C30: Onsite | D30: BSIT 4B | E30: Mendoza, Christian Gabriel D. | F30: 3 | G30: 4 | H30: 2 | I30: 2 | J30: =SUM(G30:I30) -> 8 | K30: 2 | L30: 3 | M30: =SUM(K30:L30) -> 5 | N30: =F30+J30+M30 -> 16 | O30: 3 | P30: 2 | Q30: 2 | R30: 2 | S30: 3 | T30: 2 | U30: 2 | V30: 2 | W30: 2 | X30: 3 | Y30: 2 | Z30: 2 | AA30: 2 | AB30: 3 | AC30: 3 | AD30: 3 | AE30: 2 | AF30: 2 | AG30: 3 | AH30: 3 | AK30: 2 | AL30: 2 | AM30: =ROUND(AVERAGE(O30:AL30),0) -> 2 | AN30: 2 | AO30: 3 | AP30: 4 | AQ30: 4 | AR30: 4 | AS30: 4 | AT30: 3 | AU30: 4 | AV30: 4 | AW30: =SUM(AN30,AO30,AP30,AQ30,AR30,AS30,AT30,AU30,AV30) -> 32
A31: Group 1 | B31: Social Security System (Dilima Branch) | C31: Onsite | D31: BSIT 4B | E31: Padao, Rene Vincent A. | F31: 3 | G31: 4 | H31: 2 | I31: 2 | J31: =SUM(G31:I31) -> 8 | K31: 2 | L31: 3 | M31: =SUM(K31:L31) -> 5 | N31: =F31+J31+M31 -> 16 | O31: 3 | P31: 3 | Q31: 3 | R31: 3 | S31: 3 | T31: 3 | U31: 3 | V31: 3 | W31: 3 | X31: 3 | Y31: 3 | Z31: 3 | AA31: 3 | AB31: 3 | AC31: 3 | AD31: 3 | AE31: 2 | AF31: 2 | AG31: 3 | AH31: 3 | AK31: 3 | AL31: 2 | AM31: =ROUND(AVERAGE(O31:AL31),0) -> 3 | AN31: 4 | AO31: 4 | AP31: 4 | AQ31: 4 | AR31: 4 | AS31: 4 | AT31: 4 | AU31: 4 | AV31: 4 | AW31: =SUM(AN31,AO31,AP31,AQ31,AR31,AS31,AT31,AU31,AV31) -> 36
A32: Group 1 | B32: Social Security System (Dilima Branch) | C32: Onsite | D32: BSIT 4B | E32: Mercader, Wynnie | F32: 5 | G32: 3 | H32: 3 | I32: 2 | J32: =SUM(G32:I32) -> 8 | K32: 2 | L32: 3 | M32: =SUM(K32:L32) -> 5 | N32: =F32+J32+M32 -> 18 | O32: 3 | P32: 2 | Q32: 2 | R32: 3 | S32: 3 | T32: 3 | U32: 3 | V32: 3 | W32: 3 | X32: 3 | Y32: 3 | Z32: 3 | AA32: 3 | AB32: 3 | AC32: 3 | AD32: 2 | AE32: 2 | AF32: 2 | AG32: 2 | AH32: 2 | AK32: 3 | AL32: 2 | AM32: =ROUND(AVERAGE(O32:AL32),0) -> 3 | AN32: 4 | AO32: 4 | AP32: 4 | AQ32: 3 | AR32: 3 | AS32: 4 | AT32: 4 | AU32: 3 | AV32: 4 | AW32: =SUM(AN32,AO32,AP32,AQ32,AR32,AS32,AT32,AU32,AV32) -> 33
A33: Group 1 | B33: I-Ride Mototranspo Urban or Passenger Land Transportation | C33: Hybrid | D33: BSIT 4B | E33: Castro, Geoffrey Z. | F33: 5 | G33: 2 | H33: 2 | I33: 1 | J33: =SUM(G33:I33) -> 5 | K33: 2 | L33: 1 | M33: =SUM(K33:L33) -> 3 | N33: =F33+J33+M33 -> 13 | O33: 2 | P33: 2 | Q33: 2 | R33: 3 | S33: 3 | T33: 3 | U33: 3 | V33: 3 | W33: 2 | X33: 2 | Y33: 2 | Z33: 2 | AA33: 2 | AB33: 2 | AC33: 2 | AD33: 3 | AE33: 3 | AF33: 3 | AG33: 3 | AH33: 3 | AK33: 2.5 | AL33: 1.75 | AM33: =ROUND(AVERAGE(O33:AL33),0) -> 2 | AN33: 3 | AO33: 3 | AP33: 3 | AQ33: 3 | AR33: 3 | AS33: 3 | AT33: 3 | AU33: 3 | AV33: 3 | AW33: =SUM(AN33,AO33,AP33,AQ33,AR33,AS33,AT33,AU33,AV33) -> 27
A34: Group 1 | B34: Bitag Multimedia Network | C34: Onsite | D34: BSIT 4B | E34: Mendoza, Kristian C. | F34: 5 | G34: 3 | H34: 3 | I34: 2 | J34: =SUM(G34:I34) -> 8 | K34: 2 | L34: 2 | M34: =SUM(K34:L34) -> 4 | N34: =F34+J34+M34 -> 17 | O34: 3 | P34: 3 | Q34: 3 | R34: 3 | S34: 3 | T34: 3 | U34: 3 | V34: 2 | W34: 3 | X34: 3 | Y34: 3 | Z34: 3 | AA34: 3 | AB34: 3 | AC34: 3 | AD34: 2 | AE34: 3 | AF34: 3 | AG34: 2 | AH34: 2 | AK34: 2.5 | AL34: 2.5 | AM34: =ROUND(AVERAGE(O34:AL34),0) -> 3 | AN34: 4 | AO34: 4 | AP34: 4 | AQ34: 4 | AR34: 4 | AS34: 4 | AT34: 3 | AU34: 4 | AV34: 4 | AW34: =SUM(AN34,AO34,AP34,AQ34,AR34,AS34,AT34,AU34,AV34) -> 35
A35: Group 2 | B35: Management Information System | C35: Onsite | D35: BSIT 4B | E35: Martin, Vince Erickson V. | F35: 3 | G35: 4 | H35: 2 | I35: 2 | J35: =SUM(G35:I35) -> 8 | K35: 2 | L35: 2 | M35: =SUM(K35:L35) -> 4 | N35: =F35+J35+M35 -> 15 | O35: 3 | P35: 3 | Q35: 3 | R35: 3 | S35: 3 | T35: 3 | U35: 3 | V35: 3 | W35: 3 | X35: 3 | Y35: 3 | Z35: 3 | AA35: 3 | AB35: 3 | AC35: 3 | AD35: 3 | AE35: 3 | AF35: 3 | AG35: 3 | AH35: 3 | AK35: 2.5 | AL35: 2.5 | AM35: =ROUND(AVERAGE(O35:AL35),0) -> 3 | AN35: 4 | AO35: 4 | AP35: 4 | AQ35: 4 | AR35: 4 | AS35: 4 | AT35: 4 | AU35: 4 | AV35: 4 | AW35: =SUM(AN35,AO35,AP35,AQ35,AR35,AS35,AT35,AU35,AV35) -> 36
A36: Group 2 | B36: Social Security System (Dilima Branch) | C36: Onsite | D36: BSIT 4B | E36: Malonga, Emmanuel D. | F36: 5 | G36: 4 | H36: 3 | I36: 2 | J36: =SUM(G36:I36) -> 9 | K36: 2 | L36: 3 | M36: =SUM(K36:L36) -> 5 | N36: =F36+J36+M36 -> 19 | O36: 3 | P36: 3 | Q36: 3 | R36: 3 | S36: 3 | T36: 3 | U36: 3 | V36: 3 | W36: 3 | X36: 3 | Y36: 3 | Z36: 3 | AA36: 3 | AB36: 3 | AC36: 3 | AD36: 3 | AE36: 2 | AF36: 2 | AG36: 3 | AH36: 3 | AK36: 3 | AL36: 2 | AM36: =ROUND(AVERAGE(O36:AL36),0) -> 3 | AN36: 4 | AO36: 4 | AP36: 4 | AQ36: 4 | AR36: 4 | AS36: 4 | AT36: 4 | AU36: 4 | AV36: 4 | AW36: =SUM(AN36,AO36,AP36,AQ36,AR36,AS36,AT36,AU36,AV36) -> 36
A37: Group 2 | B37: LBC Express INC. | C37: Onsite | D37: BSIT 4B | E37: Mananog, Kim Cedrick S. | F37: 5 | G37: 4 | H37: 3 | I37: 2 | J37: =SUM(G37:I37) -> 9 | K37: 2 | L37: 3 | M37: =SUM(K37:L37) -> 5 | N37: =F37+J37+M37 -> 19 | O37: 3 | P37: 3 | Q37: 3 | R37: 3 | S37: 2 | T37: 3 | U37: 2 | V37: 3 | W37: 3 | X37: 2 | Y37: 2 | Z37: 3 | AA37: 2 | AB37: 3 | AC37: 2 | AD37: 3 | AE37: 2 | AF37: 2 | AG37: 3 | AH37: 3 | AK37: 2 | AL37: 2 | AM37: =ROUND(AVERAGE(O37:AL37),0) -> 3 | AN37: 4 | AO37: 4 | AP37: 4 | AQ37: 4 | AR37: 4 | AS37: 4 | AT37: 3 | AU37: 3 | AV37: 4 | AW37: =SUM(AN37,AO37,AP37,AQ37,AR37,AS37,AT37,AU37,AV37) -> 34
A38: Group 2 | B38: BASC - Main Library | C38: Onsite | D38: BSIT 4B | E38: Villegas, Jhon Lorenz | F38: 5 | G38: 4 | H38: 2 | I38: 2 | J38: =SUM(G38:I38) -> 8 | K38: 2 | L38: 2 | M38: =SUM(K38:L38) -> 4 | N38: =F38+J38+M38 -> 17 | O38: 2 | P38: 3 | Q38: 3 | R38: 2 | S38: 3 | T38: 2 | U38: 3 | V38: 3 | W38: 3 | X38: 3 | Y38: 3 | Z38: 3 | AA38: 3 | AB38: 3 | AC38: 3 | AD38: 2 | AE38: 3 | AF38: 3 | AG38: 2 | AH38: 2 | AK38: 2.5 | AL38: 2.5 | AM38: =ROUND(AVERAGE(O38:AL38),0) -> 3 | AN38: 3 | AO38: 3 | AP38: 4 | AQ38: 4 | AR38: 3 | AS38: 4 | AT38: 4 | AU38: 4 | AV38: 4 | AW38: =SUM(AN38,AO38,AP38,AQ38,AR38,AS38,AT38,AU38,AV38) -> 33
A39: Group 2 | B39: National Irregation Administration - Regional Office | C39: Onsite | D39: BSIT 4B | E39: Delos Reyes, Ma. Luis V | F39: 2.5 | G39: 3 | H39: 2 | I39: 2 | J39: =SUM(G39:I39) -> 7 | K39: 2 | L39: 2 | M39: =SUM(K39:L39) -> 4 | N39: =F39+J39+M39 -> 13.5 | O39: 3 | P39: 3 | Q39: 3 | R39: 3 | S39: 3 | T39: 3 | U39: 3 | V39: 2 | W39: 3 | X39: 3 | Y39: 3 | Z39: 3 | AA39: 3 | AB39: 3 | AC39: 3 | AD39: 3 | AE39: 3 | AF39: 3 | AG39: 3 | AH39: 3 | AK39: 2.5 | AL39: 2.5 | AM39: =ROUND(AVERAGE(O39:AL39),0) -> 3 | AN39: 4 | AO39: 4 | AP39: 3 | AQ39: 4 | AR39: 4 | AS39: 4 | AT39: 4 | AU39: 4 | AV39: 4 | AW39: =SUM(AN39,AO39,AP39,AQ39,AR39,AS39,AT39,AU39,AV39) -> 35
A40: Group 2 | B40: Panrama Technologies Enterprises | C40: Onsite | D40: BSIT 4B | E40: Velarde, Wendell D. | F40: 5 | G40: 4 | H40: 3 | I40: 2 | J40: =SUM(G40:I40) -> 9 | K40: 2 | L40: 2 | M40: =SUM(K40:L40) -> 4 | N40: =F40+J40+M40 -> 18 | O40: 3 | P40: 3 | Q40: 3 | R40: 3 | S40: 3 | T40: 3 | U40: 2 | V40: 2 | W40: 2 | X40: 3 | Y40: 3 | Z40: 3 | AA40: 3 | AB40: 3 | AC40: 2 | AD40: 3 | AE40: 2 | AF40: 2 | AG40: 3 | AH40: 3 | AK40: 3 | AL40: 3 | AM40: =ROUND(AVERAGE(O40:AL40),0) -> 3 | AN40: 3 | AO40: 3 | AP40: 3 | AQ40: 3 | AR40: 3 | AS40: 4 | AT40: 4 | AU40: 4 | AV40: 4 | AW40: =SUM(AN40,AO40,AP40,AQ40,AR40,AS40,AT40,AU40,AV40) -> 31
...

Sheet Pivot Table 3

Sheet Pivot Table 2

Sheet Descriptive Statistics
B2: Frequency | C2: Percentage
A3: Section
A4: BSIT 4A | B4: =COUNTIF(OJTSummarized!$D$3:$D$84,A4) -> 25 | C4: =B4/$B$7 -> 0.30487805
A5: BSIT 4B | B5: =COUNTIF(OJTSummarized!$D$3:$D$84,A5) -> 28 | C5: =B5/$B$7 -> 0.34146341
A6: BSIT 4C | B6: =COUNTIF(OJTSummarized!$D$3:$D$84,A6) -> 29 | C6: =B6/$B$7 -> 0.35365854
B7: =SUM(B4:B6) -> 82 | C7: =SUM(C4:C6) -> 1
A8: Mode of Delivery
A9: Online | B9: =COUNTIF(OJTSummarized!$C$3:$C$84,A9) -> 16 | C9: =B9/$B$12 -> 0.19512195
A10: Onsite | B10: =COUNTIF(OJTSummarized!$C$3:$C$84,A10) -> 58 | C10: =B10/$B$12 -> 0.70731707
A11: Hybrid | B11: =COUNTIF(OJTSummarized!$C$3:$C$84,A11) -> 8 | C11: =B11/$B$12 -> 0.097560976
B12: =SUM(B9:B11) -> 82 | C12: =SUM(C9:C11) -> 1
A13: Host Training Establishment
A14: Accounting Service, Philippine Army
A15: Ameticia Digital Marketing
A16: APCargo Logistic Network Corporation
A17: Asia Source College Inc.
A18: Asiapro Multipurpose Cooperative
A19: BASC - CA-GS Library
A20: BASC - CoE
A21: BASC - IAS
A22: BASC - IVM
A23: BASC - IPTBMO
A24: BASC - Main Library
... A28: Buildnet Construction Inc.

Sheet Excel Functions
B1: Statistic | C1: Excel Formula | D1: Purpose
B2: Count | C2: =COUNT(OJTSummarized!$J$3:$J$84) -> 82 | D2: Number of numeric responses
B3: Mean | C3: =AVERAGE(OJTSummarized!$J$3:$J$84) -> 8.0487805 | D3: Arithmetic average
B4: Standard Error | C4: =_xlfn.STDEV.S(OJTSummarized!$J$3:$J$84)/SQRT(COUNT(OJTSummarized!$J$3:$J$84)) -> 0.15607968 | D4: Precision of the sample mean
B5: Median | C5: =MEDIAN(OJTSummarized!$J$3:$J$84) -> 8 | D5: Middle value
B6: Mode | C6: =MODE(OJTSummarized!$J$3:$J$84) -> 9 | D6: Most frequent value
B7: Standard Deviation | C7: =_xlfn.STDEV.S(OJTSummarized!$J$3:$J$84) -> 1.4133616 | D7: Spread around the mean
A8: INTERNSHIP PERFORMANCE RATING | B8: Sample Variance | C8: =_xlfn.VAR.S(OJTSummarized!$J$3:$J$982) -> 1.9975911 | D8: Squared sample standard deviation
B9: Kurtosis | C9: =KURT(OJTSummarized!$J$3:$J$84) -> -0.91568448 | D9: Distribution tail/peak shape
B10: Skewness | C10: =SKEW(OJTSummarized!$J$3:$J$84) -> -0.46473848 | D10: Distribution asymmetry
B11: Range | C11: =MAX(OJTSummarized!$J$3:$J$84)-MIN(OJTSummarized!$J$3:$J$84) -> 5 | D11: Highest minus lowest
B12: Minimum | C12: =MIN(OJTSummarized!$J$3:$J$84) -> 5 | D12: Lowest value
B13: Maximum | C13: =MAX(OJTSummarized!$J$3:$J$84) -> 10 | D13: Highest value
B14: Sum | C14: =SUM(OJTSummarized!$J$3:$J$84) -> 660 | D14: Total of numeric responses
B16: Count | C16: =COUNT(OJTSummarized!$M$3:$M$84) -> 82 | D16: Number of numeric responses
B17: Mean | C17: =AVERAGE(OJTSummarized!$M$3:$M$84) -> 3.8780488 | D17: Arithmetic average
B18: Standard Error | C18: =_xlfn.STDEV.S(OJTSummarized!$M$3:$M$84)/SQRT(COUNT(OJTSummarized!$M$3:$M$84)) -> 0.078356815 | D18: Precision of the sample mean
B19: Median | C19: =MEDIAN(OJTSummarized!$M$3:$M$84) -> 4 | D19: Middle value
B20: Mode | C20: =MODE(OJTSummarized!$M$3:$M$84) -> 4 | D20: Most frequent value
B21: Standard Deviation | C21: =_xlfn.STDEV.S(OJTSummarized!$M$3:$M$84) -> 0.70955113 | D21: Spread around the mean
A22: INTERNSHIP FEEDBACK MECHANISM | B22: Sample Variance | C22: =_xlfn.VAR.S(OJTSummarized!$M$3:$M$84) -> 0.50346281 | D22: Squared sample standard deviation
B23: Kurtosis | C23: =KURT(OJTSummarized!$M$3:$M$84) -> -0.4976903 | D23: Distribution tail/peak shape
B24: Skewness | C24: =SKEW(OJTSummarized!$M$3:$M$84) -> -0.032999837 | D24: Distribution asymmetry
B25: Range | C25: =MAX(OJTSummarized!$M$3:$M$84)-MIN(OJTSummarized!$M$3:$M$84) -> 3 | D25: Highest minus lowest
B26: Minimum | C26: =MIN(OJTSummarized!$M$3:$M$84) -> 2 | D26: Lowest value
B27: Maximum | C27: =MAX(OJTSummarized!$M$3:$M$84) -> 5 | D27: Highest value
B28: Sum | C28: =SUM(OJTSummarized!$M$3:$M$84) -> 318 | D28: Total of numeric responses
B30: Count | C30: =COUNT(OJTSummarized!$N$3:$N$84) -> 82 | D30: Number of numeric responses
B31: Mean | C31: =AVERAGE(OJTSummarized!$N$3:$N$84) -> 16.378049 | D31: Arithmetic average
B32: Standard Error | C32: =_xlfn.STDEV.S(OJTSummarized!$N$3:$N$84)/SQRT(COUNT(OJTSummarized!$N$3:$N$84)) -> 0.26736035 | D32: Precision of the sample mean
B33: Median | C33: =MEDIAN(OJTSummarized!$N$3:$N$84) -> 17 | D33: Middle value
B34: Mode | C34: =MODE(OJTSummarized!$M$3:$M$84) -> 4 | D34: Most frequent value
B35: Standard Deviation | C35: =_xlfn.STDEV.S(OJTSummarized!$N$3:$N$84) -> 2.4210509 | D35: Spread around the mean
A36: INTERNSHIP MONITORING AND EVALUATION | B36: Sample Variance | C36: =_xlfn.VAR.S(OJTSummarized!$N$3:$N$84) -> 5.8614875 | D36: Squared sample standard deviation
B37: Kurtosis | C37: =KURT(OJTSummarized!$N$3:$N$84) -> -1.0277089 | D37: Distribution tail/peak shape
B38: Skewness | C38: =SKEW(OJTSummarized!$N$3:$N$84) -> -0.57618397 | D38: Distribution asymmetry
B39: Range | C39: =MAX(OJTSummarized!$N$3:$N$84)-MIN(OJTSummarized!$N$3:$N$84) -> 9 | D39: Highest minus lowest
B40: Minimum | C40: =MIN(OJTSummarized!$N$3:$N$84) -> 11 | D40: Lowest value
B41: Maximum | C41: =MAX(OJTSummarized!$N$3:$N$84) -> 20 | D41: Highest value
B42: Sum | C42: =SUM(OJTSummarized!$N$3:$N$84) -> 1343 | D42: Total of numeric responses

Sheet Data Analysis Output
A1: Statistic | B1: Performance Rating | C1: Feedback Mechanism | D1: Monitoring and Evaluation
A2: Mean | B2: =AVERAGE(OJTSummarized!$J$3:$J$982) -> 8.0487805 | C2: =AVERAGE(OJTSummarized!$M$3:$M$982) -> 3.8780488 | D2: =AVERAGE(OJTSummarized!$N$3:$N$982) -> 16.378049
A3: Standard Error | B3: =_xlfn.STDEV.S(OJTSummarized!$J$3:$J$982)/SQRT(COUNT(OJTSummarized!$J$3:$J$982)) -> 0.15607968 | C3: =_xlfn.STDEV.S(OJTSummarized!$M$3:$M$982)/SQRT(COUNT(OJTSummarized!$M$3:$M$982)) -> 0.078356815 | D3: =_xlfn.STDEV.S(OJTSummarized!$N$3:$N$982)/SQRT(COUNT(OJTSummarized!$N$3:$N$982)) -> 0.26736035
A4: Median | B4: =MEDIAN(OJTSummarized!$J$3:$J$982) -> 8 | C4: =MEDIAN(OJTSummarized!$M$3:$M$982) -> 4 | D4: =MEDIAN(OJTSummarized!$N$3:$N$982) -> 17
A5: Mode | B5: =MODE(OJTSummarized!$M$3:$M$982) -> 4 | C5: =MODE(OJTSummarized!$M$3:$M$982) -> 4 | D5: =MODE(OJTSummarized!$M$3:$M$982) -> 4
A6: Standard Deviation | B6: =_xlfn.STDEV.S(OJTSummarized!$J$3:$J$982) -> 1.4133616 | C6: =_xlfn.STDEV.S(OJTSummarized!$M$3:$M$982) -> 0.70955113 | D6: =_xlfn.STDEV.S(OJTSummarized!$N$3:$N$982) -> 2.4210509
A7: Sample Variance | B7: =_xlfn.VAR.S(OJTSummarized!$J$3:$J$982) -> 1.9975911 | C7: =_xlfn.VAR.S(OJTSummarized!$M$3:$M$982) -> 0.50346281 | D7: =_xlfn.VAR.S(OJTSummarized!$N$3:$N$982) -> 5.8614875
A8: Kurtosis | B8: =KURT(OJTSummarized!$J$3:$J$982) -> -0.91568448 | C8: =KURT(OJTSummarized!$M$3:$M$982) -> -0.4976903 | D8: =KURT(OJTSummarized!$N$3:$N$982) -> -1.0277089
A9: Skewness | B9: =SKEW(OJTSummarized!$J$3:$J$982) -> -0.46473848 | C9: =SKEW(OJTSummarized!$M$3:$M$982) -> -0.032999837 | D9: =SKEW(OJTSummarized!$N$3:$N$982) -> -0.57618397
A10: Range | B10: =MAX(OJTSummarized!$J$3:$J$982)-MIN(OJTSummarized!$J$3:$J$982) -> 5 | C10: =MAX(OJTSummarized!$M$3:$M$982)-MIN(OJTSummarized!$M$3:$M$982) -> 3 | D10: =MAX(OJTSummarized!$N$3:$N$982)-MIN(OJTSummarized!$N$3:$N$982) -> 9
A11: Minimum | B11: =MIN(OJTSummarized!$J$3:$J$982) -> 5 | C11: =MIN(OJTSummarized!$M$3:$M$982) -> 2 | D11: =MIN(OJTSummarized!$N$3:$N$982) -> 11
A12: Maximum | B12: =MAX(OJTSummarized!$J$3:$J$982) -> 10 | C12: =MAX(OJTSummarized!$M$3:$M$982) -> 5 | D12: =MAX(OJTSummarized!$N$3:$N$982) -> 20
A13: Sum | B13: =SUM(OJTSummarized!$J$3:$J$982) -> 660 | C13: =SUM(OJTSummarized!$M$3:$M$982) -> 318 | D13: =SUM(OJTSummarized!$N$3:$N$982) -> 1343
A14: Count | B14: =COUNT(OJTSummarized!$J$3:$J$982) -> 82 | C14: =COUNT(OJTSummarized!$M$3:$M$982) -> 82 | D14: =COUNT(OJTSummarized!$N$3:$N$982) -> 82

Sheet Activity 15 - Descriptive Stats
A1: ACTIVITY 15: DESCRIPTIVE STATISTICS
A2: Statistic | B2: Internship Performance Rating | C2: Internship Feedback Mechanism | D2: Internship Monitoring and Evaluation
A3: Number of responses | B3: =COUNT(OJTSummarized!J3:J84) -> 82 | C3: =COUNT(OJTSummarized!M3:M84) -> 82 | D3: =COUNT(OJTSummarized!N3:N84) -> 82
A4: Mean | B4: =AVERAGE(OJTSummarized!J3:J84) -> 8.0487805 | C4: =AVERAGE(OJTSummarized!M3:M84) -> 3.8780488 | D4: =AVERAGE(OJTSummarized!N3:N84) -> 16.378049
A5: Median | B5: =MEDIAN(OJTSummarized!J3:J84) -> 8 | C5: =MEDIAN(OJTSummarized!M3:M84) -> 4 | D5: =MEDIAN(OJTSummarized!N3:N84) -> 17
A6: Mode | B6: =MODE(OJTSummarized!J3:J84) -> 9 | C6: =MODE(OJTSummarized!M3:M84) -> 4 | D6: =MODE(OJTSummarized!N3:N84) -> 18
A7: Standard deviation (sample) | B7: =_xlfn.STDEV.S(OJTSummarized!J3:J84) -> 1.4133616 | C7: =_xlfn.STDEV.S(OJTSummarized!M3:M84) -> 0.70955113 | D7: =_xlfn.STDEV.S(OJTSummarized!N3:N84) -> 2.4210509
A8: Variance (sample) | B8: =_xlfn.VAR.S(OJTSummarized!J3:J84) -> 1.9975911 | C8: =_xlfn.VAR.S(OJTSummarized!M3:M84) -> 0.50346281 | D8: =_xlfn.VAR.S(OJTSummarized!N3:N84) -> 5.8614875
A9: Minimum | B9: =MIN(OJTSummarized!J3:J84) -> 5 | C9: =MIN(OJTSummarized!M3:M84) -> 2 | D9: =MIN(OJTSummarized!N3:N84) -> 11
A10: Maximum | B10: =MAX(OJTSummarized!J3:J84) -> 10 | C10: =MAX(OJTSummarized!M3:M84) -> 5 | D10: =MAX(OJTSummarized!N3:N84) -> 20
A11: Range | B11: =MAX(OJTSummarized!J3:J84)-MIN(OJTSummarized!J3:J84) -> 5 | C11: =MAX(OJTSummarized!M3:M84)-MIN(OJTSummarized!M3:M84) -> 3 | D11: =MAX(OJTSummarized!N3:N84)-MIN(OJTSummarized!N3:N84) -> 9
A12: Standard error | B12: =_xlfn.STDEV.S(OJTSummarized!J3:J84)/SQRT(COUNT(OJTSummarized!J3:J84)) -> 0.15607968 | C12: =_xlfn.STDEV.S(OJTSummarized!M3:M84)/SQRT(COUNT(OJTSummarized!M3:M84)) -> 0.078356815 | D12: =_xlfn.STDEV.S(OJTSummarized!N3:N84)/SQRT(COUNT(OJTSummarized!N3:N84)) -> 0.26736035
A16: The internship performance rating obtained a mean of 8.05 and a median of 8.00, indicating that the average and middle scores are relatively high. The standard deviation of 1.41 shows a moderate variation in the respondents' ratings, while the range of 5 indicates a difference between the lowest score of 5 and the highest score of 10. The kurtosis of -0.92 suggests that the distribution is flatter than a normal distribution, while the skewness of -0.46 indicates a slightly negatively skewed distribution, meaning the scores have a longer tail toward the lower values. Overall, the results suggest that the interns generally received high performance ratings, although some respondents gave lower scores than others.
A18: The internship feedback mechanism received a mean of 3.88 and a median of 4.00, showing that most respondents gave positive ratings. The standard deviation of 0.71 indicates that the responses were fairly close to the average. The range of 3 means that the ratings varied from 2 to 5. The kurtosis of -0.50 suggests a flatter distribution, while the skewness of -0.03 indicates that the responses were almost evenly distributed. Overall, the results show that respondents were generally satisfied with the internship feedback process, but there is still room for improvement.
A21: The internship monitoring and evaluation domain had a mean of 16.38 and a median of 17.00, showing that the typical score was slightly higher than the average. The standard deviation of 2.42 indicates some differences in respondents’ scores, while the range of 9 shows that scores went from 11 to 20. The kurtosis of -1.03 suggests a flatter distribution, while the skewness of -0.58 indicates that more scores were toward the higher end. Overall, the results show that respondents generally received high scores in internship monitoring and evaluation, although their experiences and assessments were not exactly the same.

Sheet Platform Comparison
A1: COMPARISON: GOOGLE SHEETS VS MICROSOFT EXCEL
A2: Platform | B2: Advantages | C2: Disadvantages
A3: Google Sheets | B3: Google Sheets is free with a Google account and allows easy real-time collaboration. Group members can view edits and comments, while changes are automatically saved to Google Drive. It also supports statistical functions like AVERAGE, MEDIAN, MODE, STDEV.S, VAR.S, MIN, and MAX. Since it works directly in a web browser, it is convenient and accessible from different devices. | C3: Works best with an internet connection, although offline access is available when enabled. Handling large datasets or complicated analyses may sometimes be slower. It also has fewer advanced statistical features than Excel, and some formulas or formatting may change when opening Excel files.
A4: Microsoft Excel | B4: Offers advanced statistical functions and the Data Analysis ToolPak for detailed analysis. It can manage large datasets and complex workbooks efficiently. It also supports various formulas, charts, PivotTables, and formatting options. Excel works offline and is commonly used for data analysis and reporting. | C4: A paid license or subscription may be needed to access all features. Sharing separate file copies can make collaboration and tracking changes more difficult. The Data Analysis ToolPak may also require manual activation, and beginners might find some tools and settings complicated to use.
